<?xml version="1.0"?>
<!-- Minimal UR5 kinematic chain for ikpy (no mesh/collision). Base to flange. -->
<robot name="ur5">
  <link name="base_link"/>
  <joint name="shoulder_pan_joint" type="revolute">
    <parent link="base_link"/>
    <child link="shoulder_link"/>
    <origin xyz="0 0 0.089159" rpy="0 0 0"/>
    <axis xyz="0 0 1"/>
    <limit lower="-6.283185307" upper="6.283185307" effort="0" velocity="0"/>
  </joint>
  <link name="shoulder_link"/>
  <joint name="shoulder_lift_joint" type="revolute">
    <parent link="shoulder_link"/>
    <child link="upper_arm_link"/>
    <origin xyz="0 0.135 0" rpy="0 0 0"/>
    <axis xyz="0 1 0"/>
    <limit lower="-6.283185307" upper="6.283185307" effort="0" velocity="0"/>
  </joint>
  <link name="upper_arm_link"/>
  <joint name="elbow_joint" type="revolute">
    <parent link="upper_arm_link"/>
    <child link="forearm_link"/>
    <origin xyz="0 -0.425 0" rpy="0 0 0"/>
    <axis xyz="0 1 0"/>
    <limit lower="-6.283185307" upper="6.283185307" effort="0" velocity="0"/>
  </joint>
  <link name="forearm_link"/>
  <joint name="wrist_1_joint" type="revolute">
    <parent link="forearm_link"/>
    <child link="wrist_1_link"/>
    <origin xyz="0 -0.39225 0" rpy="0 0 0"/>
    <axis xyz="0 1 0"/>
    <limit lower="-6.283185307" upper="6.283185307" effort="0" velocity="0"/>
  </joint>
  <link name="wrist_1_link"/>
  <joint name="wrist_2_joint" type="revolute">
    <parent link="wrist_1_link"/>
    <child link="wrist_2_link"/>
    <origin xyz="0 0 0.10915" rpy="0 0 0"/>
    <axis xyz="0 1 0"/>
    <limit lower="-6.283185307" upper="6.283185307" effort="0" velocity="0"/>
  </joint>
  <link name="wrist_2_link"/>
  <joint name="wrist_3_joint" type="revolute">
    <parent link="wrist_2_link"/>
    <child link="wrist_3_link"/>
    <origin xyz="0 0 0.09465" rpy="0 0 0"/>
    <axis xyz="0 1 0"/>
    <limit lower="-6.283185307" upper="6.283185307" effort="0" velocity="0"/>
  </joint>
  <link name="wrist_3_link"/>
  <joint name="ee_fixed" type="fixed">
    <parent link="wrist_3_link"/>
    <child link="ee_link"/>
    <origin xyz="0 0 0.0823" rpy="0 0 0"/>
  </joint>
  <link name="ee_link"/>
</robot>
